2024-03-27 07:58:26,847 INFO    MainThread:100632 [wandb_setup.py:_flush():71] setting env: {}
2024-03-27 07:58:26,847 INFO    MainThread:100632 [wandb_setup.py:_flush():71] setting login settings: {}
2024-03-27 07:58:26,847 INFO    MainThread:100632 [wandb_init.py:_log_setup():371] Logging user logs to ./wandb/run-20240327_075826-23kzvh93/logs/debug.log
2024-03-27 07:58:26,847 INFO    MainThread:100632 [wandb_init.py:_log_setup():372] Logging internal logs to ./wandb/run-20240327_075826-23kzvh93/logs/debug-internal.log
2024-03-27 07:58:26,847 INFO    MainThread:100632 [wandb_init.py:_jupyter_setup():321] configuring jupyter hooks <wandb.sdk.wandb_init._WandbInit object at 0x7fe5ad549570>
2024-03-27 07:58:26,848 INFO    MainThread:100632 [wandb_init.py:init():404] calling init triggers
2024-03-27 07:58:26,848 INFO    MainThread:100632 [wandb_init.py:init():409] wandb.init called with sweep_config: {}
config: {}
2024-03-27 07:58:26,848 INFO    MainThread:100632 [wandb_init.py:init():460] starting backend
2024-03-27 07:58:26,848 INFO    MainThread:100632 [backend.py:_multiprocessing_setup():99] multiprocessing start_methods=fork,spawn,forkserver, using: spawn
2024-03-27 07:58:26,853 INFO    MainThread:100632 [backend.py:ensure_launched():216] starting backend process...
2024-03-27 07:58:26,855 INFO    MainThread:100632 [backend.py:ensure_launched():221] started backend process with pid: 104156
2024-03-27 07:58:26,855 INFO    MainThread:100632 [wandb_init.py:init():469] backend started and connected
2024-03-27 07:58:26,861 INFO    MainThread:100632 [wandb_run.py:_label_probe_notebook():911] probe notebook
2024-03-27 07:58:26,863 ERROR   MainThread:100632 [jupyter.py:attempt_kaggle_load_ipynb():279] Unable to load kaggle notebook
Traceback (most recent call last):
  File "/opt/conda/lib/python3.10/site-packages/wandb/jupyter.py", line 273, in attempt_kaggle_load_ipynb
    client = kaggle.UserSessionClient()
  File "/root/.local/lib/python3.10/site-packages/kaggle_session.py", line 14, in __init__
    self.web_client = KaggleWebClient()
  File "/root/.local/lib/python3.10/site-packages/kaggle_web_client.py", line 29, in __init__
    raise CredentialError(
kaggle_web_client.CredentialError: A JWT Token is required to call Kaggle, but none found in environment variable KAGGLE_USER_SECRETS_TOKEN
2024-03-27 07:58:26,865 INFO    MainThread:100632 [wandb_run.py:_label_probe_notebook():921] Unable to probe notebook: 'NoneType' object has no attribute 'get'
2024-03-27 07:58:26,865 INFO    MainThread:100632 [wandb_init.py:init():533] updated telemetry
2024-03-27 07:58:26,872 INFO    MainThread:100632 [wandb_init.py:init():563] communicating current version
2024-03-27 07:58:28,017 INFO    MainThread:100632 [wandb_init.py:init():568] got version response upgrade_message: "wandb version 0.16.5 is available!  To upgrade, please run:\n $ pip install wandb --upgrade"

2024-03-27 07:58:28,018 INFO    MainThread:100632 [wandb_init.py:init():578] communicating run to backend with 30 second timeout
2024-03-27 07:58:28,136 INFO    MainThread:100632 [wandb_init.py:init():606] starting run threads in backend
2024-03-27 07:58:33,143 INFO    MainThread:100632 [wandb_run.py:_console_start():1810] atexit reg
2024-03-27 07:58:33,144 INFO    MainThread:100632 [wandb_run.py:_redirect():1684] redirect: SettingsConsole.WRAP
2024-03-27 07:58:33,144 INFO    MainThread:100632 [wandb_run.py:_redirect():1721] Wrapping output streams.
2024-03-27 07:58:33,145 INFO    MainThread:100632 [wandb_run.py:_redirect():1745] Redirects installed.
2024-03-27 07:58:33,145 INFO    MainThread:100632 [wandb_init.py:init():633] run started, returning control to user process
2024-03-27 08:00:21,973 INFO    MainThread:100632 [wandb_run.py:finish():1457] finishing run hzume/pii-002-002/23kzvh93
2024-03-27 08:00:21,974 INFO    MainThread:100632 [jupyter.py:save_history():429] not saving jupyter history
2024-03-27 08:00:21,974 INFO    MainThread:100632 [jupyter.py:save_ipynb():374] not saving jupyter notebook
2024-03-27 08:00:21,974 INFO    MainThread:100632 [wandb_init.py:_jupyter_teardown():303] cleaning up jupyter logic
2024-03-27 08:00:21,975 INFO    MainThread:100632 [wandb_run.py:_atexit_cleanup():1780] got exitcode: 0
2024-03-27 08:00:21,994 INFO    MainThread:100632 [wandb_run.py:_restore():1752] restore
2024-03-27 08:00:22,085 INFO    MainThread:100632 [wandb_run.py:_restore():1752] restore
