2024-03-27 07:58:27,936 INFO    MainThread:104156 [internal.py:wandb_internal():87] W&B internal server running at pid: 104156, started at: 2024-03-27 07:58:27.936143
2024-03-27 07:58:27,938 DEBUG   HandlerThread:104156 [handler.py:handle_request():130] handle_request: check_version
2024-03-27 07:58:27,938 INFO    WriterThread:104156 [datastore.py:open_for_write():77] open: ./wandb/run-20240327_075826-23kzvh93/run-23kzvh93.wandb
2024-03-27 07:58:27,939 DEBUG   SenderThread:104156 [sender.py:send():234] send: header
2024-03-27 07:58:27,939 DEBUG   SenderThread:104156 [sender.py:send_request():248] send_request: check_version
2024-03-27 07:58:28,018 DEBUG   SenderThread:104156 [sender.py:send():234] send: run
2024-03-27 07:58:28,021 INFO    SenderThread:104156 [sender.py:_maybe_setup_resume():484] checking resume status for None/pii-002-002/23kzvh93
2024-03-27 07:58:28,136 INFO    SenderThread:104156 [dir_watcher.py:__init__():169] watching files in: ./wandb/run-20240327_075826-23kzvh93/files
2024-03-27 07:58:28,136 INFO    SenderThread:104156 [sender.py:_start_run_threads():804] run started: 23kzvh93 with start time 1711526306
2024-03-27 07:58:28,136 DEBUG   SenderThread:104156 [sender.py:send():234] send: summary
2024-03-27 07:58:28,136 INFO    SenderThread:104156 [sender.py:_save_file():939] saving file wandb-summary.json with policy end
2024-03-27 07:58:28,137 DEBUG   HandlerThread:104156 [handler.py:handle_request():130] handle_request: run_start
2024-03-27 07:58:29,138 INFO    Thread-8  :104156 [dir_watcher.py:_on_file_created():217] file/dir created: ./wandb/run-20240327_075826-23kzvh93/files/wandb-summary.json
2024-03-27 07:58:31,396 DEBUG   HandlerThread:104156 [meta.py:__init__():40] meta init
2024-03-27 07:58:31,396 DEBUG   HandlerThread:104156 [meta.py:__init__():54] meta init done
2024-03-27 07:58:31,396 DEBUG   HandlerThread:104156 [meta.py:probe():214] probe
2024-03-27 07:58:31,413 DEBUG   HandlerThread:104156 [meta.py:_setup_git():204] setup git
2024-03-27 07:58:32,024 INFO    WriterThread:104156 [datastore.py:close():281] close: ./wandb/run-20240327_075826-23kzvh93/run-23kzvh93.wandb
2024-03-27 07:58:32,225 INFO    SenderThread:104156 [sender.py:finish():1070] shutting down sender
2024-03-27 07:58:32,225 INFO    SenderThread:104156 [dir_watcher.py:finish():283] shutting down directory watcher
2024-03-27 07:58:33,225 INFO    SenderThread:104156 [dir_watcher.py:_on_file_created():217] file/dir created: ./wandb/run-20240327_075826-23kzvh93/files/output.log
2024-03-27 07:58:33,225 INFO    SenderThread:104156 [dir_watcher.py:finish():313] scan: ./wandb/run-20240327_075826-23kzvh93/files
2024-03-27 07:58:33,225 INFO    SenderThread:104156 [dir_watcher.py:finish():327] scan save: ./wandb/run-20240327_075826-23kzvh93/files/wandb-summary.json wandb-summary.json
2024-03-27 07:58:33,225 INFO    SenderThread:104156 [dir_watcher.py:finish():327] scan save: ./wandb/run-20240327_075826-23kzvh93/files/output.log output.log
2024-03-27 07:58:33,226 INFO    SenderThread:104156 [dir_watcher.py:finish():327] scan save: ./wandb/run-20240327_075826-23kzvh93/files/config.yaml config.yaml
2024-03-27 07:58:33,230 INFO    SenderThread:104156 [file_pusher.py:finish():177] shutting down file pusher
2024-03-27 07:58:33,230 INFO    SenderThread:104156 [file_pusher.py:join():182] waiting for file pusher
2024-03-27 07:58:33,447 INFO    Thread-11 :104156 [upload_job.py:push():137] Uploaded file ./wandb/run-20240327_075826-23kzvh93/files/wandb-summary.json
2024-03-27 07:58:33,505 INFO    Thread-12 :104156 [upload_job.py:push():137] Uploaded file ./wandb/run-20240327_075826-23kzvh93/files/config.yaml
2024-03-27 07:58:33,752 ERROR   MainThread:104156 [internal.py:wandb_internal():158] Thread HandlerThread:
Traceback (most recent call last):
  File "/opt/conda/lib/python3.10/site-packages/wandb/sdk/internal/internal_util.py", line 52, in run
    self._run()
  File "/opt/conda/lib/python3.10/site-packages/wandb/sdk/internal/internal_util.py", line 102, in _run
    self._process(record)
  File "/opt/conda/lib/python3.10/site-packages/wandb/sdk/internal/internal.py", line 246, in _process
    self._hm.handle(record)
  File "/opt/conda/lib/python3.10/site-packages/wandb/sdk/internal/handler.py", line 122, in handle
    handler(record)
  File "/opt/conda/lib/python3.10/site-packages/wandb/sdk/internal/handler.py", line 132, in handle_request
    handler(record)
  File "/opt/conda/lib/python3.10/site-packages/wandb/sdk/internal/handler.py", line 589, in handle_request_run_start
    run_meta.probe()
  File "/opt/conda/lib/python3.10/site-packages/wandb/sdk/internal/meta.py", line 235, in probe
    self._setup_git()
  File "/opt/conda/lib/python3.10/site-packages/wandb/sdk/internal/meta.py", line 210, in _setup_git
    self.data["root"] = self._git.root or self.data["root"] or os.getcwd()
  File "/opt/conda/lib/python3.10/site-packages/wandb/sdk/lib/git.py", line 50, in root
    return self.repo.git.rev_parse("--show-toplevel")
  File "/opt/conda/lib/python3.10/site-packages/git/cmd.py", line 741, in <lambda>
    return lambda *args, **kwargs: self._call_process(name, *args, **kwargs)
  File "/opt/conda/lib/python3.10/site-packages/git/cmd.py", line 1315, in _call_process
    return self.execute(call, **exec_kwargs)
  File "/opt/conda/lib/python3.10/site-packages/git/cmd.py", line 1109, in execute
    raise GitCommandError(redacted_command, status, stderr_value, stdout_value)
git.exc.GitCommandError: Cmd('git') failed due to: exit code(128)
  cmdline: git rev-parse --show-toplevel
  stderr: 'fatal: detected dubious ownership in repository at '/kaggle'
To add an exception for this directory, call:

	git config --global --add safe.directory /kaggle'
2024-03-27 07:58:35,767 INFO    MainThread:104156 [internal.py:handle_exit():77] Internal process exited
