Thread HandlerThread:
Traceback (most recent call last):
  File "/opt/conda/lib/python3.10/site-packages/wandb/sdk/internal/internal_util.py", line 52, in run
    self._run()
  File "/opt/conda/lib/python3.10/site-packages/wandb/sdk/internal/internal_util.py", line 102, in _run
    self._process(record)
  File "/opt/conda/lib/python3.10/site-packages/wandb/sdk/internal/internal.py", line 246, in _process
    self._hm.handle(record)
  File "/opt/conda/lib/python3.10/site-packages/wandb/sdk/internal/handler.py", line 122, in handle
    handler(record)
  File "/opt/conda/lib/python3.10/site-packages/wandb/sdk/internal/handler.py", line 132, in handle_request
    handler(record)
  File "/opt/conda/lib/python3.10/site-packages/wandb/sdk/internal/handler.py", line 589, in handle_request_run_start
    run_meta.probe()
  File "/opt/conda/lib/python3.10/site-packages/wandb/sdk/internal/meta.py", line 235, in probe
    self._setup_git()
  File "/opt/conda/lib/python3.10/site-packages/wandb/sdk/internal/meta.py", line 210, in _setup_git
    self.data["root"] = self._git.root or self.data["root"] or os.getcwd()
  File "/opt/conda/lib/python3.10/site-packages/wandb/sdk/lib/git.py", line 50, in root
    return self.repo.git.rev_parse("--show-toplevel")
  File "/opt/conda/lib/python3.10/site-packages/git/cmd.py", line 741, in <lambda>
    return lambda *args, **kwargs: self._call_process(name, *args, **kwargs)
  File "/opt/conda/lib/python3.10/site-packages/git/cmd.py", line 1315, in _call_process
    return self.execute(call, **exec_kwargs)
  File "/opt/conda/lib/python3.10/site-packages/git/cmd.py", line 1109, in execute
    raise GitCommandError(redacted_command, status, stderr_value, stdout_value)
git.exc.GitCommandError: Cmd('git') failed due to: exit code(128)
  cmdline: git rev-parse --show-toplevel
  stderr: 'fatal: detected dubious ownership in repository at '/kaggle'
To add an exception for this directory, call:
	git config --global --add safe.directory /kaggle'
wandb: ERROR Internal wandb error: file data was not synced
Exception in thread NetStatThr:
Traceback (most recent call last):
  File "/opt/conda/lib/python3.10/threading.py", line 1016, in _bootstrap_inner
    self.run()
  File "/opt/conda/lib/python3.10/threading.py", line 953, in run
    self._target(*self._args, **self._kwargs)
  File "/opt/conda/lib/python3.10/site-packages/wandb/sdk/wandb_run.py", line 152, in check_network_status
    status_response = self._interface.communicate_network_status()
  File "/opt/conda/lib/python3.10/site-packages/wandb/sdk/interface/interface.py", line 125, in communicate_network_status
    resp = self._communicate_network_status(status)
  File "/opt/conda/lib/python3.10/site-packages/wandb/sdk/interface/interface_shared.py", line 388, in _communicate_network_status
    resp = self._communicate(req, local=True)
  File "/opt/conda/lib/python3.10/site-packages/wandb/sdk/interface/interface_shared.py", line 213, in _communicate
    return self._communicate_async(rec, local=local).get(timeout=timeout)
  File "/opt/conda/lib/python3.10/site-packages/wandb/sdk/interface/interface_shared.py", line 218, in _communicate_async
    raise Exception("The wandb backend process has shutdown")
Exception: The wandb backend process has shutdown
Exception in thread ChkStopThr:
Traceback (most recent call last):
  File "/opt/conda/lib/python3.10/threading.py", line 1016, in _bootstrap_inner
    self.run()
  File "/opt/conda/lib/python3.10/threading.py", line 953, in run
    self._target(*self._args, **self._kwargs)
  File "/opt/conda/lib/python3.10/site-packages/wandb/sdk/wandb_run.py", line 170, in check_status
    status_response = self._interface.communicate_stop_status()
  File "/opt/conda/lib/python3.10/site-packages/wandb/sdk/interface/interface.py", line 114, in communicate_stop_status
    resp = self._communicate_stop_status(status)
  File "/opt/conda/lib/python3.10/site-packages/wandb/sdk/interface/interface_shared.py", line 378, in _communicate_stop_status
    resp = self._communicate(req, local=True)
  File "/opt/conda/lib/python3.10/site-packages/wandb/sdk/interface/interface_shared.py", line 213, in _communicate
    return self._communicate_async(rec, local=local).get(timeout=timeout)
  File "/opt/conda/lib/python3.10/site-packages/wandb/sdk/interface/interface_shared.py", line 218, in _communicate_async
    raise Exception("The wandb backend process has shutdown")
Exception: The wandb backend process has shutdown
epoch 0 validation loss 2.8252460956573486
epoch 0 validation scores {'ents_p': 0.0, 'ents_r': 0.0, 'ents_f5': 0.0, 'ents_per_type': {'PHONE_NUM': {'p': 0.0, 'r': 0.0, 'f5': 0.0}, 'STREET_ADDRESS': {'p': 0.0, 'r': 0.0, 'f5': 0.0}, 'NAME_STUDENT': {'p': 0.0, 'r': 0.0, 'f5': 0.0}, 'EMAIL': {'p': 0.0, 'r': 0.0, 'f5': 0.0}, 'ID_NUM': {'p': 0.0, 'r': 0.0, 'f5': 0.0}, 'URL_PERSONAL': {'p': 0.0, 'r': 0.0, 'f5': 0.0}, 'USERNAME': {'p': 0.0, 'r': 0.0, 'f5': 0.0}}}
/opt/conda/lib/python3.10/site-packages/pytorch_lightning/trainer/call.py:53: UserWarning: Detected KeyboardInterrupt, attempting graceful shutdown...
  rank_zero_warn("Detected KeyboardInterrupt, attempting graceful shutdown...")